Workbook

Sheet Customers
A1: id | B1: full_name | C1: email | D1: registration_date | E1: city | F1: control_id
A2: 1 | B2: Omar Smith | C2: omar.smith@example.com | D2: 43833 | E2: San Diego | F2: =IF(COUNTIF($A:$A,A2)=1,"UNICO","DUPLICADO") -> UNICO
A3: 2 | B3: Tariq Gupta | C3: tariq.gupta@example.org | D3: 44804 | E3: Cape Town | F3: =IF(COUNTIF($A:$A,A3)=1,"UNICO","DUPLICADO") -> UNICO
A4: 3 | B4: Mateo Shah | C4: mateo.shah@example.net | D4: 43832 | E4: Jakarta | F4: =IF(COUNTIF($A:$A,A4)=1,"UNICO","DUPLICADO") -> UNICO
A5: 4 | B5: Paula Flores | C5: paula.flores@example.org | D5: 43971 | E5: Cape Town | F5: =IF(COUNTIF($A:$A,A5)=1,"UNICO","DUPLICADO") -> UNICO
A6: 5 | B6: Karim Brown | C6: karim.brown@example.net | D6: 44176 | E6: Kyoto | F6: =IF(COUNTIF($A:$A,A6)=1,"UNICO","DUPLICADO") -> UNICO
A7: 6 | B7: Fatima Wang | C7: fatima.wang@example.com | D7: 44189 | E7: Oslo | F7: =IF(COUNTIF($A:$A,A7)=1,"UNICO","DUPLICADO") -> UNICO
A8: 7 | B8: Alice Hassan | C8: alice.hassan@example.net | D8: 44160 | E8: Edinburgh | F8: =IF(COUNTIF($A:$A,A8)=1,"UNICO","DUPLICADO") -> UNICO
A9: 8 | B9: Mateo Johnson | C9: mateo.johnson@example.org | D9: 44490 | E9: Bogota | F9: =IF(COUNTIF($A:$A,A9)=1,"UNICO","DUPLICADO") -> UNICO
A10: 9 | B10: Ben Murphy | C10: ben.murphy@example.org | D10: 44528 | E10: Taipei | F10: =IF(COUNTIF($A:$A,A10)=1,"UNICO","DUPLICADO") -> UNICO
A11: 10 | B11: Olivia Garcia | C11: olivia.garcia@example.org | D11: 43978 | E11: Sydney | F11: =IF(COUNTIF($A:$A,A11)=1,"UNICO","DUPLICADO") -> UNICO
A12: 11 | B12: Priya Park | C12: priya.park@example.com | D12: 44874 | E12: Dublin | F12: =IF(COUNTIF($A:$A,A12)=1,"UNICO","DUPLICADO") -> UNICO
A13: 12 | B13: James Walker | C13: james.walker@example.com | D13: 44724 | F13: =IF(COUNTIF($A:$A,A13)=1,"UNICO","DUPLICADO") -> UNICO
A14: 13 | B14: Lena Sousa | C14: lena.sousa@example.com | D14: 44828 | E14: Cairo | F14: =IF(COUNTIF($A:$A,A14)=1,"UNICO","DUPLICADO") -> UNICO
A15: 14 | B15: Mohamed Ruiz | C15: mohamed.ruiz@example.com | D15: 44914 | F15: =IF(COUNTIF($A:$A,A15)=1,"UNICO","DUPLICADO") -> UNICO
A16: 15 | B16: Hana Schneider | C16: hana.schneider@example.net | D16: 44159 | E16: Boston | F16: =IF(COUNTIF($A:$A,A16)=1,"UNICO","DUPLICADO") -> UNICO
A17: 16 | B17: Elena Walker | C17: elena.walker@example.org | D17: 44336 | E17: Ankara | F17: =IF(COUNTIF($A:$A,A17)=1,"UNICO","DUPLICADO") -> UNICO
A18: 17 | B18: Hannah Kumar | C18: hannah.kumar@example.org | D18: 44738 | F18: =IF(COUNTIF($A:$A,A18)=1,"UNICO","DUPLICADO") -> UNICO
A19: 18 | B19: Hannah Novak | C19: hannah.novak@example.net | D19: 44269 | F19: =IF(COUNTIF($A:$A,A19)=1,"UNICO","DUPLICADO") -> UNICO
A20: 19 | B20: Elena Chen | C20: elena.chen@example.com | D20: 43908 | E20: Austin | F20: =IF(COUNTIF($A:$A,A20)=1,"UNICO","DUPLICADO") -> UNICO
A21: 20 | B21: Lena Schneider | C21: lena.schneider@example.com | D21: 44615 | E21: Edinburgh | F21: =IF(COUNTIF($A:$A,A21)=1,"UNICO","DUPLICADO") -> UNICO
A22: 21 | B22: Ethan Cruz | C22: ethan.cruz@example.org | D22: 44495 | E22: Istanbul | F22: =IF(COUNTIF($A:$A,A22)=1,"UNICO","DUPLICADO") -> UNICO
A23: 22 | B23: Sara Reyes | C23: sara.reyes@example.net | D23: 44661 | F23: =IF(COUNTIF($A:$A,A23)=1,"UNICO","DUPLICADO") -> UNICO
A24: 23 | B24: Fatima Novak | C24: fatima.novak@example.org | D24: 44464 | E24: Mumbai | F24: =IF(COUNTIF($A:$A,A24)=1,"UNICO","DUPLICADO") -> UNICO
A25: 24 | B25: Sofia Zhang | C25: sofia.zhang@example.net | D25: 44199 | F25: =IF(COUNTIF($A:$A,A25)=1,"UNICO","DUPLICADO") -> UNICO
A26: 25 | B26: Mila Garcia | C26: mila.garcia@example.com | D26: 44206 | E26: Toronto | F26: =IF(COUNTIF($A:$A,A26)=1,"UNICO","DUPLICADO") -> UNICO
A27: 26 | B27: Olivia Clark | C27: olivia.clark@example.com | D27: 44531 | E27: Nairobi | F27: =IF(COUNTIF($A:$A,A27)=1,"UNICO","DUPLICADO") -> UNICO
A28: 27 | B28: Felix Garcia | C28: felix.garcia@example.org | D28: 43878 | E28: Paris | F28: =IF(COUNTIF($A:$A,A28)=1,"UNICO","DUPLICADO") -> UNICO
A29: 28 | B29: Daniel Evans | C29: daniel.evans@example.com | D29: 44788 | E29: San Diego | F29: =IF(COUNTIF($A:$A,A29)=1,"UNICO","DUPLICADO") -> UNICO
A30: 29 | B30: Felix Nguyen | C30: felix.nguyen@example.net | D30: 44862 | E30: Munich | F30: =IF(COUNTIF($A:$A,A30)=1,"UNICO","DUPLICADO") -> UNICO
A31: 30 | B31: Ethan Demir | C31: ethan.demir@example.org | D31: 44060 | E31: Barcelona | F31: =IF(COUNTIF($A:$A,A31)=1,"UNICO","DUPLICADO") -> UNICO
A32: 31 | B32: Lina Kumar | C32: lina.kumar@example.com | D32: 44143 | E32: Auckland | F32: =IF(COUNTIF($A:$A,A32)=1,"UNICO","DUPLICADO") -> UNICO
A33: 32 | B33: Karim Wilson | C33: karim.wilson@example.com | D33: 44116 | E33: Copenhagen | F33: =IF(COUNTIF($A:$A,A33)=1,"UNICO","DUPLICADO") -> UNICO
A34: 33 | B34: Noah Mendes | C34: noah.mendes@example.net | D34: 44633 | E34: Denver | F34: =IF(COUNTIF($A:$A,A34)=1,"UNICO","DUPLICADO") -> UNICO
A35: 34 | B35: Chloe Diaz | C35: chloe.diaz@example.org | D35: 44477 | F35: =IF(COUNTIF($A:$A,A35)=1,"UNICO","DUPLICADO") -> UNICO
A36: 35 | B36: Ivan Hoffmann | C36: ivan.hoffmann@example.com | D36: 44474 | E36: Budapest | F36: =IF(COUNTIF($A:$A,A36)=1,"UNICO","DUPLICADO") -> UNICO
A37: 36 | B37: Sam Kowalski | C37: sam.kowalski@example.net | D37: 43887 | E37: Izmir | F37: =IF(COUNTIF($A:$A,A37)=1,"UNICO","DUPLICADO") -> UNICO
A38: 37 | B38: Uma Shah | C38: uma.shah@example.net | D38: 44851 | E38: Vienna | F38: =IF(COUNTIF($A:$A,A38)=1,"UNICO","DUPLICADO") -> UNICO
A39: 38 | B39: Yara Garcia | C39: yara.garcia@example.net | D39: 44466 | E39: London | F39: =IF(COUNTIF($A:$A,A39)=1,"UNICO","DUPLICADO") -> UNICO
A40: 39 | B40: Lina Gomez | C40: lina.gomez@example.org | D40: 44741 | E40: Jakarta | F40: =IF(COUNTIF($A:$A,A40)=1,"UNICO","DUPLICADO") -> UNICO
...

Sheet Orders
A1: id | B1: customer_id | C1: order_date | D1: total_amount | E1: quantity | F1: discount_amount | G1: validacion_cliente | H1: control_id
A2: 1 | B2: 114 | C2: 44246.388 | D2: 4801.04 | E2: 51 | F2: 336.32 | G2: =IF(COUNTIF(Customers!$A$2:$A$1000,B2)>0,"OK","REVISAR") -> OK | H2: =IF(COUNTIF($A:$A,A2)=1,"UNICO","DUPLICADO") -> UNICO
A3: 2 | B3: 18 | C3: 44814.401 | D3: 4653.26 | E3: 62 | F3: 8.11 | G3: =IF(COUNTIF(Customers!$A$2:$A$1000,B3)>0,"OK","REVISAR") -> OK | H3: =IF(COUNTIF($A:$A,A3)=1,"UNICO","DUPLICADO") -> UNICO
A4: 3 | B4: 164 | C4: 44899.571 | D4: 10.01 | E4: 63 | F4: 55.91 | G4: =IF(COUNTIF(Customers!$A$2:$A$1000,B4)>0,"OK","REVISAR") -> OK | H4: =IF(COUNTIF($A:$A,A4)=1,"UNICO","DUPLICADO") -> UNICO
A5: 4 | B5: 215 | C5: 44580.084 | D5: 29.39 | E5: 36 | F5: 298.34 | G5: =IF(COUNTIF(Customers!$A$2:$A$1000,B5)>0,"OK","REVISAR") -> OK | H5: =IF(COUNTIF($A:$A,A5)=1,"UNICO","DUPLICADO") -> UNICO
A6: 5 | B6: 88 | C6: 44918.683 | D6: 733.33 | E6: 53 | F6: 153.20 | G6: =IF(COUNTIF(Customers!$A$2:$A$1000,B6)>0,"OK","REVISAR") -> OK | H6: =IF(COUNTIF($A:$A,A6)=1,"UNICO","DUPLICADO") -> UNICO
A7: 6 | B7: 73 | C7: 44509.376 | D7: 803.09 | E7: 27 | F7: 124.04 | G7: =IF(COUNTIF(Customers!$A$2:$A$1000,B7)>0,"OK","REVISAR") -> OK | H7: =IF(COUNTIF($A:$A,A7)=1,"UNICO","DUPLICADO") -> UNICO
A8: 7 | B8: 129 | C8: 44808.554 | D8: 29.99 | E8: 35 | F8: 10.07 | G8: =IF(COUNTIF(Customers!$A$2:$A$1000,B8)>0,"OK","REVISAR") -> OK | H8: =IF(COUNTIF($A:$A,A8)=1,"UNICO","DUPLICADO") -> UNICO
A9: 8 | B9: 137 | C9: 44739.556 | D9: 3024.74 | E9: 44 | F9: 0.18 | G9: =IF(COUNTIF(Customers!$A$2:$A$1000,B9)>0,"OK","REVISAR") -> OK | H9: =IF(COUNTIF($A:$A,A9)=1,"UNICO","DUPLICADO") -> UNICO
A10: 9 | B10: 204 | C10: 44457.497 | D10: 4034.03 | E10: 55 | F10: 388.69 | G10: =IF(COUNTIF(Customers!$A$2:$A$1000,B10)>0,"OK","REVISAR") -> OK | H10: =IF(COUNTIF($A:$A,A10)=1,"UNICO","DUPLICADO") -> UNICO
A11: 10 | B11: 16 | C11: 44552.61 | D11: 1708.86 | E11: 47 | F11: 351.28 | G11: =IF(COUNTIF(Customers!$A$2:$A$1000,B11)>0,"OK","REVISAR") -> OK | H11: =IF(COUNTIF($A:$A,A11)=1,"UNICO","DUPLICADO") -> UNICO
A12: 11 | B12: 13 | C12: 44652.822 | D12: 2498.86 | E12: 26 | F12: 136.52 | G12: =IF(COUNTIF(Customers!$A$2:$A$1000,B12)>0,"OK","REVISAR") -> OK | H12: =IF(COUNTIF($A:$A,A12)=1,"UNICO","DUPLICADO") -> UNICO
A13: 12 | B13: 214 | C13: 44694.67 | D13: 57.07 | E13: 43 | F13: 485.04 | G13: =IF(COUNTIF(Customers!$A$2:$A$1000,B13)>0,"OK","REVISAR") -> OK | H13: =IF(COUNTIF($A:$A,A13)=1,"UNICO","DUPLICADO") -> UNICO
... A20: 19 | B20: 88 | C20: 44271.485 | D20: 2299.27 | E20: 48 | F20: 7.58 | G20: =IF(COUNTIF(Customers!$A$2:$A$1000,B20)>0,"OK","REVISAR") -> OK | H20: =IF(COUNTIF($A:$A,A20)=1,"UNICO","DUPLICADO") -> UNICO
A21: 20 | B21: 131 | C21: 44905.316 | E21: 34 | F21: 264.94 | G21: =IF(COUNTIF(Customers!$A$2:$A$1000,B21)>0,"OK","REVISAR") -> OK | H21: =IF(COUNTIF($A:$A,A21)=1,"UNICO","DUPLICADO") -> UNICO
A22: 21 | B22: 146 | C22: 44739.39 | D22: 431.66 | E22: 52 | F22: 442.16 | G22: =IF(COUNTIF(Customers!$A$2:$A$1000,B22)>0,"OK","REVISAR") -> OK | H22: =IF(COUNTIF($A:$A,A22)=1,"UNICO","DUPLICADO") -> UNICO
A23: 22 | B23: 150 | C23: 44527.72 | D23: 1719.18 | E23: 44 | F23: 311.39 | G23: =IF(COUNTIF(Customers!$A$2:$A$1000,B23)>0,"OK","REVISAR") -> OK | H23: =IF(COUNTIF($A:$A,A23)=1,"UNICO","DUPLICADO") -> UNICO
A24: 23 | B24: 171 | C24: 44573.591 | E24: 62 | F24: 205.03 | G24: =IF(COUNTIF(Customers!$A$2:$A$1000,B24)>0,"OK","REVISAR") -> OK | H24: =IF(COUNTIF($A:$A,A24)=1,"UNICO","DUPLICADO") -> UNICO
A25: 24 | B25: 160 | C25: 44360.708 | D25: 1878.62 | E25: 59 | F25: 39.01 | G25: =IF(COUNTIF(Customers!$A$2:$A$1000,B25)>0,"OK","REVISAR") -> OK | H25: =IF(COUNTIF($A:$A,A25)=1,"UNICO","DUPLICADO") -> UNICO
A26: 25 | B26: 247 | C26: 44728.36 | D26: 31.52 | E26: 38 | F26: 428.07 | G26: =IF(COUNTIF(Customers!$A$2:$A$1000,B26)>0,"OK","REVISAR") -> OK | H26: =IF(COUNTIF($A:$A,A26)=1,"UNICO","DUPLICADO") -> UNICO
A27: 26 | B27: 141 | C27: 44813.685 | D27: 4794.59 | E27: 39 | F27: 74.24 | G27: =IF(COUNTIF(Customers!$A$2:$A$1000,B27)>0,"OK","REVISAR") -> OK | H27: =IF(COUNTIF($A:$A,A27)=1,"UNICO","DUPLICADO") -> UNICO
A28: 27 | B28: 153 | C28: 44750.724 | D28: 343.66 | E28: 68 | F28: 327.85 | G28: =IF(COUNTIF(Customers!$A$2:$A$1000,B28)>0,"OK","REVISAR") -> OK | H28: =IF(COUNTIF($A:$A,A28)=1,"UNICO","DUPLICADO") -> UNICO
A29: 28 | B29: 203 | C29: 44353.069 | D29: 336.89 | E29: 58 | F29: 83.79 | G29: =IF(COUNTIF(Customers!$A$2:$A$1000,B29)>0,"OK","REVISAR") -> OK | H29: =IF(COUNTIF($A:$A,A29)=1,"UNICO","DUPLICADO") -> UNICO
A30: 29 | B30: 224 | C30: 44323.487 | D30: 17.77 | E30: 63 | F30: 477.61 | G30: =IF(COUNTIF(Customers!$A$2:$A$1000,B30)>0,"OK","REVISAR") -> OK | H30: =IF(COUNTIF($A:$A,A30)=1,"UNICO","DUPLICADO") -> UNICO
A31: 30 | B31: 118 | C31: 44877.58 | D31: 16.20 | E31: 63 | F31: 394.92 | G31: =IF(COUNTIF(Customers!$A$2:$A$1000,B31)>0,"OK","REVISAR") -> OK | H31: =IF(COUNTIF($A:$A,A31)=1,"UNICO","DUPLICADO") -> UNICO
A32: 31 | B32: 164 | C32: 44381.633 | D32: 2193.56 | E32: 68 | F32: 31.82 | G32: =IF(COUNTIF(Customers!$A$2:$A$1000,B32)>0,"OK","REVISAR") -> OK | H32: =IF(COUNTIF($A:$A,A32)=1,"UNICO","DUPLICADO") -> UNICO
A33: 32 | B33: 28 | C33: 44525.526 | D33: 4219.57 | E33: 58 | F33: 246.57 | G33: =IF(COUNTIF(Customers!$A$2:$A$1000,B33)>0,"OK","REVISAR") -> OK | H33: =IF(COUNTIF($A:$A,A33)=1,"UNICO","DUPLICADO") -> UNICO
A34: 33 | B34: 86 | C34: 44663.808 | D34: 24.00 | E34: 33 | F34: 123.99 | G34: =IF(COUNTIF(Customers!$A$2:$A$1000,B34)>0,"OK","REVISAR") -> OK | H34: =IF(COUNTIF($A:$A,A34)=1,"UNICO","DUPLICADO") -> UNICO
A35: 34 | B35: 10 | C35: 44734.573 | D35: 193.52 | E35: 46 | F35: 1.41 | G35: =IF(COUNTIF(Customers!$A$2:$A$1000,B35)>0,"OK","REVISAR") -> OK | H35: =IF(COUNTIF($A:$A,A35)=1,"UNICO","DUPLICADO") -> UNICO
A36: 35 | B36: 55 | C36: 44669.495 | D36: 38.03 | E36: 66 | F36: 108.14 | G36: =IF(COUNTIF(Customers!$A$2:$A$1000,B36)>0,"OK","REVISAR") -> OK | H36: =IF(COUNTIF($A:$A,A36)=1,"UNICO","DUPLICADO") -> UNICO
... A45: 44 | B45: 138 | C45: 44454.601 | D45: 4887.30 | E45: 70 | F45: 194.89 | G45: =IF(COUNTIF(Customers!$A$2:$A$1000,B45)>0,"OK","REVISAR") -> OK | H45: =IF(COUNTIF($A:$A,A45)=1,"UNICO","DUPLICADO") -> UNICO
A46: 45 | B46: 246 | C46: 44921.692 | E46: 64 | F46: 485.53 | G46: =IF(COUNTIF(Customers!$A$2:$A$1000,B46)>0,"OK","REVISAR") -> OK | H46: =IF(COUNTIF($A:$A,A46)=1,"UNICO","DUPLICADO") -> UNICO
A47: 46 | B47: 7 | C47: 44370.608 | D47: 4273.47 | E47: 31 | F47: 47.11 | G47: =IF(COUNTIF(Customers!$A$2:$A$1000,B47)>0,"OK","REVISAR") -> OK | H47: =IF(COUNTIF($A:$A,A47)=1,"UNICO","DUPLICADO") -> UNICO
A48: 47 | B48: 186 | C48: 44795.706 | D48: 21.52 | E48: 58 | F48: 453.13 | G48: =IF(COUNTIF(Customers!$A$2:$A$1000,B48)>0,"OK","REVISAR") -> OK | H48: =IF(COUNTIF($A:$A,A48)=1,"UNICO","DUPLICADO") -> UNICO
A49: 48 | B49: 227 | C49: 44832.82 | D49: 3486.81 | E49: 17 | F49: 310.02 | G49: =IF(COUNTIF(Customers!$A$2:$A$1000,B49)>0,"OK","REVISAR") -> OK | H49: =IF(COUNTIF($A:$A,A49)=1,"UNICO","DUPLICADO") -> UNICO
A50: 49 | B50: 36 | C50: 44589.449 | D50: 12.73 | E50: 64 | F50: 36.52 | G50: =IF(COUNTIF(Customers!$A$2:$A$1000,B50)>0,"OK","REVISAR") -> OK | H50: =IF(COUNTIF($A:$A,A50)=1,"UNICO","DUPLICADO") -> UNICO
A51: 50 | B51: 87 | C51: 44500.676 | D51: 11.54 | E51: 47 | F51: 271.02 | G51: =IF(COUNTIF(Customers!$A$2:$A$1000,B51)>0,"OK","REVISAR") -> OK | H51: =IF(COUNTIF($A:$A,A51)=1,"UNICO","DUPLICADO") -> UNICO
A52: 51 | B52: 57 | C52: 44212.397 | D52: 831.64 | E52: 59 | F52: 0.14 | G52: =IF(COUNTIF(Customers!$A$2:$A$1000,B52)>0,"OK","REVISAR") -> OK | H52: =IF(COUNTIF($A:$A,A52)=1,"UNICO","DUPLICADO") -> UNICO
A53: 52 | B53: 236 | C53: 44730.387 | D53: 278.16 | E53: 39 | F53: 34.62 | G53: =IF(COUNTIF(Customers!$A$2:$A$1000,B53)>0,"OK","REVISAR") -> OK | H53: =IF(COUNTIF($A:$A,A53)=1,"UNICO","DUPLICADO") -> UNICO
A54: 53 | B54: 6 | C54: 44555.305 | D54: 32.20 | E54: 42 | F54: 62.10 | G54: =IF(COUNTIF(Customers!$A$2:$A$1000,B54)>0,"OK","REVISAR") -> OK | H54: =IF(COUNTIF($A:$A,A54)=1,"UNICO","DUPLICADO") -> UNICO
...

Sheet Payments
A1: id | B1: order_id | C1: payment_method | D1: payment_date | E1: transaction_fee | F1: validation_order | G1: control_id
A2: 1 | B2: 42 | C2: PayPal | D2: 44493.374 | E2: 40.07 | F2: =IF(COUNTIF(Orders!$A$2:$A$1000,B2)>0,"OK","REVISAR") -> OK | G2: =IF(COUNTIF($A:$A,A2)=1,"UNICO","DUPLICADO") -> UNICO
A3: 2 | B3: 206 | C3: PayPal | D3: 44200.505 | E3: 10.17 | F3: =IF(COUNTIF(Orders!$A$2:$A$1000,B3)>0,"OK","REVISAR") -> OK | G3: =IF(COUNTIF($A:$A,A3)=1,"UNICO","DUPLICADO") -> UNICO
A4: 3 | B4: 420 | C4: Gift Card | D4: 44537.656 | E4: 2.54 | F4: =IF(COUNTIF(Orders!$A$2:$A$1000,B4)>0,"OK","REVISAR") -> OK | G4: =IF(COUNTIF($A:$A,A4)=1,"UNICO","DUPLICADO") -> UNICO
A5: 4 | B5: 284 | C5: Credit Card | D5: 44761.499 | E5: 46.73 | F5: =IF(COUNTIF(Orders!$A$2:$A$1000,B5)>0,"OK","REVISAR") -> OK | G5: =IF(COUNTIF($A:$A,A5)=1,"UNICO","DUPLICADO") -> UNICO
A6: 5 | B6: 427 | C6: Bank Transfer | D6: 44275.39 | E6: 19.77 | F6: =IF(COUNTIF(Orders!$A$2:$A$1000,B6)>0,"OK","REVISAR") -> OK | G6: =IF(COUNTIF($A:$A,A6)=1,"UNICO","DUPLICADO") -> UNICO
A7: 6 | B7: 424 | C7: Gift Card | D7: 44539.572 | E7: 0.80 | F7: =IF(COUNTIF(Orders!$A$2:$A$1000,B7)>0,"OK","REVISAR") -> OK | G7: =IF(COUNTIF($A:$A,A7)=1,"UNICO","DUPLICADO") -> UNICO
A8: 7 | B8: 577 | C8: Credit Card | D8: 44359.672 | E8: 41.81 | F8: =IF(COUNTIF(Orders!$A$2:$A$1000,B8)>0,"OK","REVISAR") -> OK | G8: =IF(COUNTIF($A:$A,A8)=1,"UNICO","DUPLICADO") -> UNICO
A9: 8 | B9: 453 | C9: Gift Card | D9: 44235.503 | E9: 41.73 | F9: =IF(COUNTIF(Orders!$A$2:$A$1000,B9)>0,"OK","REVISAR") -> OK | G9: =IF(COUNTIF($A:$A,A9)=1,"UNICO","DUPLICADO") -> UNICO
A10: 9 | B10: 270 | C10: Credit Card | D10: 44870.463 | E10: 13.14 | F10: =IF(COUNTIF(Orders!$A$2:$A$1000,B10)>0,"OK","REVISAR") -> OK | G10: =IF(COUNTIF($A:$A,A10)=1,"UNICO","DUPLICADO") -> UNICO
A11: 10 | B11: 393 | C11: PayPal | D11: 44659.368 | E11: 32.81 | F11: =IF(COUNTIF(Orders!$A$2:$A$1000,B11)>0,"OK","REVISAR") -> OK | G11: =IF(COUNTIF($A:$A,A11)=1,"UNICO","DUPLICADO") -> UNICO
A12: 11 | B12: 591 | C12: Gift Card | D12: 44513.454 | E12: 33.72 | F12: =IF(COUNTIF(Orders!$A$2:$A$1000,B12)>0,"OK","REVISAR") -> OK | G12: =IF(COUNTIF($A:$A,A12)=1,"UNICO","DUPLICADO") -> UNICO
A13: 12 | B13: 233 | C13: Credit Card | D13: 44659.726 | E13: 31.21 | F13: =IF(COUNTIF(Orders!$A$2:$A$1000,B13)>0,"OK","REVISAR") -> OK | G13: =IF(COUNTIF($A:$A,A13)=1,"UNICO","DUPLICADO") -> UNICO
... A601: 600 | B601: 302 | C601: PayPal | D601: 44845.53 | E601: 37.00 | F601: =IF(COUNTIF(Orders!$A$2:$A$1000,B601)>0,"OK","REVISAR") -> OK | G601: =IF(COUNTIF($A:$A,A601)=1,"UNICO","DUPLICADO") -> UNICO

Sheet Products
A1: id | B1: product_name | C1: category_id | D1: price | E1: stock_quantity | F1: rating | G1: validation_category | H1: control_id
A2: 1 | B2: toy | C2: 3 | D2: 1901.24 | E2: 559 | F2: 5 | G2: =IF(COUNTIF(Categories!$A$2:$A$1000,C2)>0,"OK","REVISAR") -> OK | H2: =IF(COUNTIF($A:$A,A2)=1,"UNICO","DUPLICADO") -> UNICO
A3: 2 | B3: software game gear | C3: 9 | D3: 36.21 | E3: 621 | F3: 4 | G3: =IF(COUNTIF(Categories!$A$2:$A$1000,C3)>0,"OK","REVISAR") -> OK | H3: =IF(COUNTIF($A:$A,A3)=1,"UNICO","DUPLICADO") -> UNICO
A4: 3 | B4: book | C4: 6 | D4: 1849.76 | E4: 535 | F4: 3 | G4: =IF(COUNTIF(Categories!$A$2:$A$1000,C4)>0,"OK","REVISAR") -> OK | H4: =IF(COUNTIF($A:$A,A4)=1,"UNICO","DUPLICADO") -> UNICO
A5: 4 | B5: appliance | C5: 3 | D5: 215.26 | E5: 629 | G5: =IF(COUNTIF(Categories!$A$2:$A$1000,C5)>0,"OK","REVISAR") -> OK | H5: =IF(COUNTIF($A:$A,A5)=1,"UNICO","DUPLICADO") -> UNICO
A6: 5 | B6: hardware kitchenware | C6: 9 | D6: 1797.51 | E6: 429 | F6: 3 | G6: =IF(COUNTIF(Categories!$A$2:$A$1000,C6)>0,"OK","REVISAR") -> OK | H6: =IF(COUNTIF($A:$A,A6)=1,"UNICO","DUPLICADO") -> UNICO
A7: 6 | B7: jewelry game | C7: 4 | E7: 378 | F7: 2 | G7: =IF(COUNTIF(Categories!$A$2:$A$1000,C7)>0,"OK","REVISAR") -> OK | H7: =IF(COUNTIF($A:$A,A7)=1,"UNICO","DUPLICADO") -> UNICO
A8: 7 | B8: book kitchenware hardware | C8: 10 | D8: 387.03 | E8: 472 | F8: 4 | G8: =IF(COUNTIF(Categories!$A$2:$A$1000,C8)>0,"OK","REVISAR") -> OK | H8: =IF(COUNTIF($A:$A,A8)=1,"UNICO","DUPLICADO") -> UNICO
A9: 8 | B9: gadget | C9: 6 | D9: 7.35 | E9: 451 | F9: 5 | G9: =IF(COUNTIF(Categories!$A$2:$A$1000,C9)>0,"OK","REVISAR") -> OK | H9: =IF(COUNTIF($A:$A,A9)=1,"UNICO","DUPLICADO") -> UNICO
A10: 9 | B10: jewelry product accessory | C10: 8 | D10: 953.63 | E10: 782 | F10: 2 | G10: =IF(COUNTIF(Categories!$A$2:$A$1000,C10)>0,"OK","REVISAR") -> OK | H10: =IF(COUNTIF($A:$A,A10)=1,"UNICO","DUPLICADO") -> UNICO
A11: 10 | B11: tool cosmetic | C11: 8 | D11: 799.39 | E11: 577 | F11: 5 | G11: =IF(COUNTIF(Categories!$A$2:$A$1000,C11)>0,"OK","REVISAR") -> OK | H11: =IF(COUNTIF($A:$A,A11)=1,"UNICO","DUPLICADO") -> UNICO
A12: 11 | B12: item accessory | C12: 9 | D12: 1029.83 | E12: 587 | F12: 4 | G12: =IF(COUNTIF(Categories!$A$2:$A$1000,C12)>0,"OK","REVISAR") -> OK | H12: =IF(COUNTIF($A:$A,A12)=1,"UNICO","DUPLICADO") -> UNICO
A13: 12 | B13: hardware | C13: 5 | D13: 988.41 | E13: 602 | F13: 5 | G13: =IF(COUNTIF(Categories!$A$2:$A$1000,C13)>0,"OK","REVISAR") -> OK | H13: =IF(COUNTIF($A:$A,A13)=1,"UNICO","DUPLICADO") -> UNICO
A14: 13 | B14: appliance cosmetic gear | C14: 1 | D14: 1767.29 | E14: 572 | F14: 5 | G14: =IF(COUNTIF(Categories!$A$2:$A$1000,C14)>0,"OK","REVISAR") -> OK | H14: =IF(COUNTIF($A:$A,A14)=1,"UNICO","DUPLICADO") -> UNICO
A15: 14 | B15: footwear | C15: 6 | E15: 555 | F15: 2 | G15: =IF(COUNTIF(Categories!$A$2:$A$1000,C15)>0,"OK","REVISAR") -> OK | H15: =IF(COUNTIF($A:$A,A15)=1,"UNICO","DUPLICADO") -> UNICO
A16: 15 | B16: footwear hardware item | C16: 8 | D16: 992.54 | E16: 702 | F16: 5 | G16: =IF(COUNTIF(Categories!$A$2:$A$1000,C16)>0,"OK","REVISAR") -> OK | H16: =IF(COUNTIF($A:$A,A16)=1,"UNICO","DUPLICADO") -> UNICO
A17: 16 | B17: kitchenware product | C17: 10 | D17: 94.92 | E17: 475 | F17: 4 | G17: =IF(COUNTIF(Categories!$A$2:$A$1000,C17)>0,"OK","REVISAR") -> OK | H17: =IF(COUNTIF($A:$A,A17)=1,"UNICO","DUPLICADO") -> UNICO
A18: 17 | B18: hardware | C18: 10 | D18: 897.92 | E18: 564 | F18: 3 | G18: =IF(COUNTIF(Categories!$A$2:$A$1000,C18)>0,"OK","REVISAR") -> OK | H18: =IF(COUNTIF($A:$A,A18)=1,"UNICO","DUPLICADO") -> UNICO
A19: 18 | B19: jewelry | C19: 10 | D19: 1412.52 | E19: 628 | F19: 5 | G19: =IF(COUNTIF(Categories!$A$2:$A$1000,C19)>0,"OK","REVISAR") -> OK | H19: =IF(COUNTIF($A:$A,A19)=1,"UNICO","DUPLICADO") -> UNICO
A20: 19 | B20: stationery | C20: 10 | D20: 315.81 | E20: 372 | F20: 3 | G20: =IF(COUNTIF(Categories!$A$2:$A$1000,C20)>0,"OK","REVISAR") -> OK | H20: =IF(COUNTIF($A:$A,A20)=1,"UNICO","DUPLICADO") -> UNICO
A21: 20 | B21: tool | C21: 3 | D21: 315.16 | E21: 671 | F21: 2 | G21: =IF(COUNTIF(Categories!$A$2:$A$1000,C21)>0,"OK","REVISAR") -> OK | H21: =IF(COUNTIF($A:$A,A21)=1,"UNICO","DUPLICADO") -> UNICO
A22: 21 | B22: book tool | C22: 2 | D22: 717.55 | E22: 356 | F22: 5 | G22: =IF(COUNTIF(Categories!$A$2:$A$1000,C22)>0,"OK","REVISAR") -> OK | H22: =IF(COUNTIF($A:$A,A22)=1,"UNICO","DUPLICADO") -> UNICO
A23: 22 | B23: clothing appliance book | C23: 5 | D23: 1792.92 | E23: 592 | G23: =IF(COUNTIF(Categories!$A$2:$A$1000,C23)>0,"OK","REVISAR") -> OK | H23: =IF(COUNTIF($A:$A,A23)=1,"UNICO","DUPLICADO") -> UNICO
A24: 23 | B24: stationery software | C24: 1 | D24: 635.90 | E24: 339 | F24: 5 | G24: =IF(COUNTIF(Categories!$A$2:$A$1000,C24)>0,"OK","REVISAR") -> OK | H24: =IF(COUNTIF($A:$A,A24)=1,"UNICO","DUPLICADO") -> UNICO
A25: 24 | B25: product gear | C25: 8 | D25: 555.22 | E25: 454 | F25: 3 | G25: =IF(COUNTIF(Categories!$A$2:$A$1000,C25)>0,"OK","REVISAR") -> OK | H25: =IF(COUNTIF($A:$A,A25)=1,"UNICO","DUPLICADO") -> UNICO
A26: 25 | B26: widget gadget gear | C26: 3 | D26: 1125.15 | E26: 418 | F26: 2 | G26: =IF(COUNTIF(Categories!$A$2:$A$1000,C26)>0,"OK","REVISAR") -> OK | H26: =IF(COUNTIF($A:$A,A26)=1,"UNICO","DUPLICADO") -> UNICO
A27: 26 | B27: game item furniture | C27: 8 | D27: 1287.75 | E27: 309 | F27: 3 | G27: =IF(COUNTIF(Categories!$A$2:$A$1000,C27)>0,"OK","REVISAR") -> OK | H27: =IF(COUNTIF($A:$A,A27)=1,"UNICO","DUPLICADO") -> UNICO
A28: 27 | B28: kitchenware stationery game | C28: 7 | D28: 791.05 | E28: 640 | F28: 2 | G28: =IF(COUNTIF(Categories!$A$2:$A$1000,C28)>0,"OK","REVISAR") -> OK | H28: =IF(COUNTIF($A:$A,A28)=1,"UNICO","DUPLICADO") -> UNICO
A29: 28 | B29: software widget game | C29: 1 | D29: 5.32 | E29: 553 | F29: 5 | G29: =IF(COUNTIF(Categories!$A$2:$A$1000,C29)>0,"OK","REVISAR") -> OK | H29: =IF(COUNTIF($A:$A,A29)=1,"UNICO","DUPLICADO") -> UNICO
A30: 29 | B30: gadget product jewelry | C30: 6 | D30: 639.56 | E30: 513 | F30: 2 | G30: =IF(COUNTIF(Categories!$A$2:$A$1000,C30)>0,"OK","REVISAR") -> OK | H30: =IF(COUNTIF($A:$A,A30)=1,"UNICO","DUPLICADO") -> UNICO
A31: 30 | B31: game widget | C31: 1 | D31: 1138.45 | E31: 389 | F31: 4 | G31: =IF(COUNTIF(Categories!$A$2:$A$1000,C31)>0,"OK","REVISAR") -> OK | H31: =IF(COUNTIF($A:$A,A31)=1,"UNICO","DUPLICADO") -> UNICO
A32: 31 | B32: gadget tool book | C32: 2 | D32: 117.53 | E32: 585 | F32: 4 | G32: =IF(COUNTIF(Categories!$A$2:$A$1000,C32)>0,"OK","REVISAR") -> OK | H32: =IF(COUNTIF($A:$A,A32)=1,"UNICO","DUPLICADO") -> UNICO
A33: 32 | B33: stationery | C33: 5 | D33: 1951.83 | E33: 386 | F33: 5 | G33: =IF(COUNTIF(Categories!$A$2:$A$1000,C33)>0,"OK","REVISAR") -> OK | H33: =IF(COUNTIF($A:$A,A33)=1,"UNICO","DUPLICADO") -> UNICO
A34: 33 | B34: book widget kitchenware | C34: 4 | D34: 11.02 | E34: 504 | F34: 2 | G34: =IF(COUNTIF(Categories!$A$2:$A$1000,C34)>0,"OK","REVISAR") -> OK | H34: =IF(COUNTIF($A:$A,A34)=1,"UNICO","DUPLICADO") -> UNICO
A35: 34 | B35: footwear gear | C35: 9 | D35: 472.49 | E35: 432 | F35: 5 | G35: =IF(COUNTIF(Categories!$A$2:$A$1000,C35)>0,"OK","REVISAR") -> OK | H35: =IF(COUNTIF($A:$A,A35)=1,"UNICO","DUPLICADO") -> UNICO
... A45: 44 | B45: kitchenware appliance | C45: 9 | D45: 20.80 | E45: 400 | F45: 5 | G45: =IF(COUNTIF(Categories!$A$2:$A$1000,C45)>0,"OK","REVISAR") -> OK | H45: =IF(COUNTIF($A:$A,A45)=1,"UNICO","DUPLICADO") -> UNICO
A46: 45 | B46: book jewelry | C46: 7 | E46: 540 | F46: 5 | G46: =IF(COUNTIF(Categories!$A$2:$A$1000,C46)>0,"OK","REVISAR") -> OK | H46: =IF(COUNTIF($A:$A,A46)=1,"UNICO","DUPLICADO") -> UNICO
A47: 46 | B47: game item clothing | C47: 5 | D47: 108.96 | E47: 865 | F47: 2 | G47: =IF(COUNTIF(Categories!$A$2:$A$1000,C47)>0,"OK","REVISAR") -> OK | H47: =IF(COUNTIF($A:$A,A47)=1,"UNICO","DUPLICADO") -> UNICO
A48: 47 | B48: widget | C48: 8 | D48: 155.84 | E48: 320 | F48: 5 | G48: =IF(COUNTIF(Categories!$A$2:$A$1000,C48)>0,"OK","REVISAR") -> OK | H48: =IF(COUNTIF($A:$A,A48)=1,"UNICO","DUPLICADO") -> UNICO
A49: 48 | B49: gadget hardware | C49: 10 | D49: 222.12 | E49: 471 | F49: 4 | G49: =IF(COUNTIF(Categories!$A$2:$A$1000,C49)>0,"OK","REVISAR") -> OK | H49: =IF(COUNTIF($A:$A,A49)=1,"UNICO","DUPLICADO") -> UNICO
...

Sheet Categories
A1: id | B1: category_name | C1: category_description | D1: average_price | E1: control_id
A2: 1 | B2: grocery toys beauty | C2: automotive home grocery health books electronics beauty jewelry garden toys sports clothing | D2: 5.92 | E2: =IF(COUNTIF($A:$A,A2)=1,"UNICO","DUPLICADO") -> UNICO
A3: 2 | B3: jewelry | C3: home electronics garden toys jewelry books health clothing sports | D3: 8.04 | E3: =IF(COUNTIF($A:$A,A3)=1,"UNICO","DUPLICADO") -> UNICO
A4: 3 | B4: grocery health | C4: toys sports electronics home health automotive clothing beauty garden jewelry grocery books | D4: 168.31 | E4: =IF(COUNTIF($A:$A,A4)=1,"UNICO","DUPLICADO") -> UNICO
A5: 4 | B5: accessories furniture | C5: books beauty toys jewelry grocery health automotive | D5: 1326.96 | E5: =IF(COUNTIF($A:$A,A5)=1,"UNICO","DUPLICADO") -> UNICO
A6: 5 | B6: home beauty | C6: jewelry toys automotive health clothing electronics grocery home garden sports books beauty | D6: 440.26 | E6: =IF(COUNTIF($A:$A,A6)=1,"UNICO","DUPLICADO") -> UNICO
A7: 6 | B7: jewelry grocery | C7: sports beauty garden jewelry clothing electronics | D7: 106.91 | E7: =IF(COUNTIF($A:$A,A7)=1,"UNICO","DUPLICADO") -> UNICO
A8: 7 | C8: electronics health jewelry grocery toys clothing | D8: 5.01 | E8: =IF(COUNTIF($A:$A,A8)=1,"UNICO","DUPLICADO") -> UNICO
A9: 8 | B9: electronics software | C9: health grocery books toys sports garden automotive home jewelry clothing | D9: 1169.23 | E9: =IF(COUNTIF($A:$A,A9)=1,"UNICO","DUPLICADO") -> UNICO
A10: 9 | C10: clothing jewelry toys beauty books electronics automotive health grocery sports garden home | D10: 68.93 | E10: =IF(COUNTIF($A:$A,A10)=1,"UNICO","DUPLICADO") -> UNICO
A11: 10 | B11: software | C11: beauty jewelry toys electronics home garden | D11: 1938.18 | E11: =IF(COUNTIF($A:$A,A11)=1,"UNICO","DUPLICADO") -> UNICO
